Traceback (most recent call last):
  File "/home/nlp-04/anaconda3/envs/kkm/lib/python3.10/site-packages/pandas/core/indexes/base.py", line 3802, in get_loc
    return self._engine.get_loc(casted_key)
  File "pandas/_libs/index.pyx", line 138, in pandas._libs.index.IndexEngine.get_loc
  File "pandas/_libs/index.pyx", line 165, in pandas._libs.index.IndexEngine.get_loc
  File "pandas/_libs/hashtable_class_helper.pxi", line 5745, in pandas._libs.hashtable.PyObjectHashTable.get_item
  File "pandas/_libs/hashtable_class_helper.pxi", line 5753, in pandas._libs.hashtable.PyObjectHashTable.get_item
KeyError: 'class'
The above exception was the direct cause of the following exception:
Traceback (most recent call last):
  File "/data/2_data_server/nlp-04/lost_technology/test.py", line 31, in <module>
    train_data["label"] = train_data["class"].apply(label_to_idx)
  File "/home/nlp-04/anaconda3/envs/kkm/lib/python3.10/site-packages/pandas/core/frame.py", line 3807, in __getitem__
    indexer = self.columns.get_loc(key)
  File "/home/nlp-04/anaconda3/envs/kkm/lib/python3.10/site-packages/pandas/core/indexes/base.py", line 3804, in get_loc
    raise KeyError(key) from err
KeyError: 'class'